Workbook
Name allowed117_fp_S_class_3757: 'Valid Values'!$AU$2:$AU$3
Name allowed117_fp_S_class_6161: 'Valid Values'!$AU$2:$AU$3
Name allowed1217_fp_S_class_3757: 'Valid Values'!$E$2:$E$11
Name allowed1316_fp_S_class_3757: 'Valid Values'!$AC$2:$AC$21
Name allowed1316_fp_S_class_6161: 'Valid Values'!$AC$2:$AC$21
Name allowed135_fp_S_class_3757: 'Valid Values'!$AO$2:$AO$26
Name allowed135_fp_S_class_6161: 'Valid Values'!$AO$2:$AO$26
Name allowed1379_fp_S_class_3757: 'Valid Values'!$W$2:$W$8
Name allowed137_fp_S_class_3757: 'Valid Values'!$Q$2:$Q$27
Name allowed1386_fp_S_class_6161: 'Valid Values'!$CB$2:$CB$564
Name allowed1388_fp_S_class_3757: 'Valid Values'!$AG$2:$AG$179
Name allowed1388_fp_S_class_6161: 'Valid Values'!$AG$2:$AG$179
Name allowed1436_fp_S_class_6161: 'Valid Values'!$CP$2:$CP$31
Name allowed1437_fp_S_class_3757: 'Valid Values'!$Y$2:$Y$20
Name allowed1437_fp_S_class_6161: 'Valid Values'!$CL$2:$CL$12
Name allowed1557_fp_S_class_3757: 'Valid Values'!$AK$2:$AK$15
Name allowed1557_fp_S_class_6161: 'Valid Values'!$AK$2:$AK$15
Name allowed1560_fp_S_class_3757: 'Valid Values'!$M$2:$M$30
Name allowed1567_fp_S_class_3757: 'Valid Values'!$AA$2:$AA$15
Name allowed1966_fp_S_class_3757: 'Valid Values'!$C$2:$C$33
Name allowed2358_fp_S_class_6161: 'Valid Values'!$CJ$2:$CJ$312
Name allowed2385_fp_S_class_3757: 'Valid Values'!$G$2:$G$44
Name allowed2385_fp_S_class_6161: 'Valid Values'!$BV$2:$BV$17
Name allowed2389_fp_S_class_3757: 'Valid Values'!$K$2:$K$5
Name allowed256_fp_S_class_3757: 'Valid Values'!$AQ$2:$AQ$3
Name allowed256_fp_S_class_6161: 'Valid Values'!$AQ$2:$AQ$3
Name allowed27_fp_S_class_6161: 'Valid Values'!$CN$2:$CN$3
Name allowed28_fp_S_class_3757: 'Valid Values'!$AM$2:$AM$4
Name allowed28_fp_S_class_6161: 'Valid Values'!$AM$2:$AM$4
Name allowed31_fp_S_class_3757: 'Valid Values'!$AS$2:$AS$3
Name allowed31_fp_S_class_6161: 'Valid Values'!$AS$2:$AS$3
Name allowed3538_fp_S_class_3757: 'Valid Values'!$I$2:$I$27
Name allowed3921_fp_S_class_6161: 'Valid Values'!$CH$2:$CH$7
Name allowed4123_fp_S_class_6161: 'Valid Values'!$BX$2:$BX$11
Name allowed4591_fp_S_class_6161: 'Valid Values'!$CF$2:$CF$6
Name allowed5471_fp_S_class_6161: 'Valid Values'!$BT$2:$BT$6
Name allowed6012_fp_S_class_6161: 'Valid Values'!$BR$2:$BR$6
Name allowed6109_fp_S_class_3757: 'Valid Values'!$A$2:$A$14
Name allowed6109_fp_S_class_6161: 'Valid Values'!$BP$2:$BP$9
Name allowed6253_fp_S_class_3757: 'Valid Values'!$AE$2:$AE$5
Name allowed647_fp_S_class_3757: 'Valid Values'!$O$2:$O$248
Name allowed647_fp_S_class_6161: 'Valid Values'!$O$2:$O$248
Name allowed807_fp_S_class_3757: 'Valid Values'!$U$2:$U$5
Name allowed807_fp_S_class_6161: 'Valid Values'!$U$2:$U$5
Name allowed8205_fp_S_class_3757: 'Valid Values'!$AW$2:$AW$4
Name allowed82_fp_S_class_6161: 'Valid Values'!$CD$2:$CD$40
Name allowed8462_fp_S_class_3757: 'Valid Values'!$AY$2:$AY$4
Name allowed8462_fp_S_class_6161: 'Valid Values'!$AY$2:$AY$4
Name allowed8653_fp_S_class_3757: 'Valid Values'!$AI$2:$AI$10
Name allowed8653_fp_S_class_6161: 'Valid Values'!$BZ$2:$BZ$4
Name allowed9007_fp_S_class_3757: 'Valid Values'!$BA$2:$BA$2
Name allowed9007_fp_S_class_6161: 'Valid Values'!$BA$2:$BA$2
Name allowed9009_fp_S_class_3757: 'Valid Values'!$BB$2:$BB$4
Name allowed9009_fp_S_class_6161: 'Valid Values'!$BB$2:$BB$4
Name allowed9011_fp_S_class_3757: 'Valid Values'!$BC$2:$BC$3
Name allowed9011_fp_S_class_6161: 'Valid Values'!$CR$2:$CR$4
Name allowed9030_fp_S_class_3757: 'Valid Values'!$BD$2:$BD$3
Name allowed9030_fp_S_class_6161: 'Valid Values'!$BD$2:$BD$3
Name allowed9031_fp_S_class_3757: 'Valid Values'!$BE$2:$BE$19
Name allowed9031_fp_S_class_6161: 'Valid Values'!$BE$2:$BE$19

Sheet Instructions
A1: New Features | D1: For Mandarin translations of product questions, please click here. All answer inputs should still be provided in English. 点击此处查看所有产品相关问题的中文翻译。
A2: Variant Grouping
A3: If you have indicated that you will provide variant grouping data via template settings, additional columns for variant grouping information have been added to the class | C3: Legends
A4: sheet. Enter a common identifier to indicate which part numbers should be grouped together, select attribute(s) to group variants by (or enter custom category if | C4: Cell Fill Colors
A5: desired category is not included in the dropdown), and provide corresponding variant attribute. Groupings that violate Wayfair's Do Not Join rules will be excluded. | C5: Light Red | D5: Missing required data
A6: If Wayfair detects additional variants, products will be grouped further after submission. | C6: Gray | D6: Not required/will be autofilled*
C7: Red | D7: Error/incorrect answer
A8: Class Sheet Instructions | C8: Blue | D8: Autofill suggested by Wayfair (review needed)
A9: All data provided in the class sheet feeds directly to the customer-facing Product Details Page (PDP), optimizes search and enables order fulfillment. Please ensure the | C9: Yellow | D9: Warning
A10: data provided is accurate and as detailed as possible. | C10: No fill | D10: Validated/no action required
D11: * For products that have already been submitted, the entire row will be filled gray and cannot be edited further
A12: Conditional Formatting
A13: Some answers to questions on the spec sheet are dependent on upstream responses, whether they are related to attributes like material type, existence of features | C13: Data Priority
A14: or compliance. Real-time cell coloring per the legend indicates whether an input is required, has an error or has a conditional rule applied. | C14: Required | D14: Data required for product to be live on site
C15: Recommended | D15: Not required but recommended to improve search and browse
A16: Error Guidance | C16: Additional | D16: Optional but enhances listings for customers
A17: Errors are highlighted on the Error Summary Tab which shows a summary of all errors across all sheets with high level details and hyperlinks to the corresponding | C17: Conditional | D17: Data may be required based on prior responses
A18: cell where the error occurred. Additionally, a new Error Status Column at the beginning of each class sheet will show the status of each row and will display the first error
A19: error message in that row, and will update as errors are resolved from left to right. | C19: Data Type
C20: Text | D20: Enter a text-based response
A21: Notes: | C21: Single-Select | D21: Select one option from a list of provided options (listed in a dropdown on the cell)
A22: • Column headers provide additional information on the data required for each column. | C22: Multi-Select | D22: Enter one or more options from a list of provided options, separated using a semi-colon (;)
A23: • Completing Recommended and Additional fields further enhances the customer experience and improves the quality of listings for better product discovery. | C23: Number* | D23: Enter a decimal numeric response with up to 2 decimal points
A24: • Marketing Copy should provide a compelling, informative overview of the product, ensuring it effectively highlights key features, benefits, and use cases. | C24: Whole Number* | D24: Enter an integer (whole number) numeric response
A25: Incorporating comprehensive, descriptive language will enable future enhancements for capturing and improving product tagging. | C25: Yes or No | D25: Enter a Yes, No or Does Not Apply response (listed in a dropdown on the cell)
A26: ◦ Provide key selling point(s)/feature(s) that differentiate your product and inform customers about your product and encourage purchase. | D26: * Does Not Apply is a valid response when applicable
A27: ◦ Either Marketing Copy OR at least 3 Feature Bullets are required. Feature bullets will be displayed on Wayfair PDP in bulleted form.
A28: • The order in which media is input may not be reflected in order of imagery on the product page.
A29: • A maximum of 3 videos can be displayed in the product media tray on the product detail page. Additional videos may be showcased through Waymore content.
A30: • If all products in a class have the same answer to a question, a default value can be set. An answer entered in the Default Answer row will be applied to all products
A31: in that class automatically. Additional products added to this class in the future will have the same default value applied as well. For any products that have a
A32: different answer than others in the class, enter the answer manually to the applicable row to bypass the default just for that question and product.
A33: • Expandable columns can be used to add additional information directly within the main spec sheet as needed for supported sections by clicking the "+" sign
A34: above the section.
A36: Instructions for Repeatable Questions
A37: Some questions can be answered multiple times based on your product set up. For example, you can add anywhere between 1 and 30 images per product.
A38: For these questions, look for the "plus" button above that section and click it to expand to more columns. You can do this multiple times until you reach the max.
A39: Depends on the type of product you are adding, some of these questions may not be shown or required.
... A66: The Failed Products tab will only appear if products in your submission fail to upload. Failed products must be added to a new template and re-uploaded before resubmission.

Sheet Error Summary
A1: This Error Summary tab lists all errors and warnings in the spec sheet. Each entry includes a link to the specific cell and detailed information about the issue.
A2: Status | B2: Location | C2: Sheet Name | D2: Supplier Part Number | E2: Field | F2: Provided Answer | G2: Error Message
A3: {=_xlfn.LET(_xlpm.cf3757_STANDARDData, GetSheetStatusData(ClassFeed3757_STANDARDTracker, ClassFeed3757_STANDARDErrors), _xlpm.cf6161_STANDARDData, GetSheetStatusData(ClassFeed6161_STANDARDTracker, ClassFeed6161_STANDARDErrors), _xlpm.stackedData, _xlfn.VSTACK(_xlpm.cf3757_STANDARDData, _xlpm.cf6161_STANDARDData), _xlfn._xlws.FILTER(_xlpm.stackedData, _xlpm.stackedData<>"", ""))} -> 0 | B3: =IF(AND(C3<>"", H3<>""), HYPERLINK("#'" & C3 & "'!" & H3, H3), "") -> 0 | C3: {=_xlfn.LET(_xlpm.cf3757_STANDARDData, GetSheetNameData(ClassFeed3757_STANDARDTracker, ClassFeed3757_STANDARDErrors, "3757 - Wall Stickers (S)"), _xlpm.cf6161_STANDARDData, GetSheetNameData(ClassFeed6161_STANDARDTracker, ClassFeed6161_STANDARDErrors, "6161 - Wallpaper (S)"), _xlpm.stackedData, _xlfn.VSTACK(_xlpm.cf3757_STANDARDData, _xlpm.cf6161_STANDARDData), _xlfn._xlws.FILTER(_xlpm.stackedData, _xlpm.stackedData<>"", ""))} -> 0 | D3: {=_xlfn.LET(_xlpm.cf3757_STANDARDPartNumbers, GetSheetSupplierPartNumbers(ClassFeed3757_STANDARDTracker, ClassFeed3757_STANDARDErrors, '3757 - Wall Stickers (S)'!$B:$B), _xlpm.cf6161_STANDARDPartNumbers, GetSheetSupplierPartNumbers(ClassFeed6161_STANDARDTracker, ClassFeed6161_STANDARDErrors, '6161 - Wallpaper (S)'!$B:$B), _xlpm.stackedPartNumbers, _xlfn.VSTACK(_xlpm.cf3757_STANDARDPartNumbers, _xlpm.cf6161_STANDARDPartNumbers), _xlfn._xlws.FILTER(_xlpm.stackedPartNumbers, _xlpm.stackedPartNumbers<>"", ""))} -> 0 | E3: {=_xlfn.LET(_xlpm.cf3757_STANDARDQuestionDisplayNames, GetErrorQuestionDisplayNames(ClassFeed3757_STANDARDHeaders, ClassFeed3757_STANDARDTracker, ClassFeed3757_STANDARDErrors), _xlpm.cf6161_STANDARDQuestionDisplayNames, GetErrorQuestionDisplayNames(ClassFeed6161_STANDARDHeaders, ClassFeed6161_STANDARDTracker, ClassFeed6161_STANDARDErrors), _xlpm.stackedQuestionDisplayNames, _xlfn.VSTACK(_xlpm.cf3757_STANDARDQuestionDisplayNames, _xlpm.cf6161_STANDARDQuestionDisplayNames), _xlfn._xlws.FILTER(_xlpm.stackedQuestionDisplayNames, _xlpm.stackedQuestionDisplayNames<>"", ""))} -> 0 | F3: {=_xlfn.LET(_xlpm.cf3757_STANDARDProvidedAnswers, GetFilteredProvidedAnswers(ClassFeed3757_STANDARDAnswers, ClassFeed3757_STANDARDErrors, ClassFeed3757_STANDARDTracker), _xlpm.cf6161_STANDARDProvidedAnswers, GetFilteredProvidedAnswers(ClassFeed6161_STANDARDAnswers, ClassFeed6161_STANDARDErrors, ClassFeed6161_STANDARDTracker), _xlpm.stackedProvidedAnswers, _xlfn.VSTACK(_xlpm.cf3757_STANDARDProvidedAnswers, _xlpm.cf6161_STANDARDProvidedAnswers), _xlfn._xlws.FILTER(_xlpm.stackedProvidedAnswers, _xlpm.stackedProvidedAnswers<>"EMPTY_ERROR", ""))} -> 0 | G3: {=_xlfn.LET(_xlpm.cf3757_STANDARDErrorMessages, _xlfn.FILTER(_xlfn.TOCOL(ClassFeed3757_STANDARDErrors), _xlfn.TOCOL((ClassFeed3757_STANDARDErrors <> "") * (ClassFeed3757_STANDARDTracker <> "Valid") * (ClassFeed3757_STANDARDTracker <> "Disabled")), ""), _xlpm.cf6161_STANDARDErrorMessages, _xlfn.FILTER(_xlfn.TOCOL(ClassFeed6161_STANDARDErrors), _xlfn.TOCOL((ClassFeed6161_STANDARDErrors <> "") * (ClassFeed6161_STANDARDTracker <> "Valid") * (ClassFeed6161_STANDARDTracker <> "Disabled")), ""), _xlpm.stackedErrorMessages, _xlfn.VSTACK(_xlpm.cf3757_STANDARDErrorMessages, _xlpm.cf6161_STANDARDErrorMessages), _xlpm.filteredMessages, _xlfn._xlws.FILTER(_xlpm.stackedErrorMessages, _xlpm.stackedErrorMessages<>"", ""), IFERROR(_xlfn.TEXTAFTER(_xlpm.filteredMessages, ":"), _xlpm.filteredMessages))} -> 0 | H3: {=_xlfn.LET(_xlpm.cf3757_STANDARDAddresses, GetSheetLocationAddresses(ClassFeed3757_STANDARDTracker, ClassFeed3757_STANDARDErrors), _xlpm.cf6161_STANDARDAddresses, GetSheetLocationAddresses(ClassFeed6161_STANDARDTracker, ClassFeed6161_STANDARDErrors), _xlpm.stackedAddresses, _xlfn.VSTACK(_xlpm.cf3757_STANDARDAddresses, _xlpm.cf6161_STANDARDAddresses), _xlfn._xlws.FILTER(_xlpm.stackedAddresses, _xlpm.stackedAddresses<>"", ""))} -> 0
B4: =IF(AND(C4<>"", H4<>""), HYPERLINK("#'" & C4 & "'!" & H4, H4), "") -> 0
B5: =IF(AND(C5<>"", H5<>""), HYPERLINK("#'" & C5 & "'!" & H5, H5), "") -> 0
B6: =IF(AND(C6<>"", H6<>""), HYPERLINK("#'" & C6 & "'!" & H6, H6), "") -> 0
B7: =IF(AND(C7<>"", H7<>""), HYPERLINK("#'" & C7 & "'!" & H7, H7), "") -> 0
B8: =IF(AND(C8<>"", H8<>""), HYPERLINK("#'" & C8 & "'!" & H8, H8), "") -> 0
B9: =IF(AND(C9<>"", H9<>""), HYPERLINK("#'" & C9 & "'!" & H9, H9), "") -> 0
B10: =IF(AND(C10<>"", H10<>""), HYPERLINK("#'" & C10 & "'!" & H10, H10), "") -> 0
B11: =IF(AND(C11<>"", H11<>""), HYPERLINK("#'" & C11 & "'!" & H11, H11), "") -> 0
B12: =IF(AND(C12<>"", H12<>""), HYPERLINK("#'" & C12 & "'!" & H12, H12), "") -> 0
B13: =IF(AND(C13<>"", H13<>""), HYPERLINK("#'" & C13 & "'!" & H13, H13), "") -> 0
B14: =IF(AND(C14<>"", H14<>""), HYPERLINK("#'" & C14 & "'!" & H14, H14), "") -> 0
B15: =IF(AND(C15<>"", H15<>""), HYPERLINK("#'" & C15 & "'!" & H15, H15), "") -> 0
... B6002: =IF(AND(C6002<>"", H6002<>""), HYPERLINK("#'" & C6002 & "'!" & H6002, H6002), "") -> 0

Sheet 3757 - Wall Stickers (S)
B1: 9000 | C1: 9001 | D1: 9005 | E1: 9006 | F1: 9007 | G1: 9008 | H1: 9009 | I1: 9010 | J1: 9011 | K1: 9012 | L1: 9011 | M1: 9012 | N1: 9011 | O1: 9012 | P1: 9017 | Q1: 9070 | R1: 9018 | S1: 9019 | T1: 9020 | U1: 9021 | V1: 9021 | W1: 9021 | X1: 9021 | Y1: 9021 | Z1: 9021 | AA1: 9021 | AB1: 9021 | AC1: 9004 | AD1: 9026 | AE1: 9027 | AF1: 9028 | AG1: 9029 | AH1: 9030 | AI1: 9031 | AJ1: 9032 | AK1: 9033 | AL1: 9034 | AM1: 9035 | AN1: 9036 | AO1: 9037 | AP1: 9038 | AQ1: 9039 | AR1: 9040 | AS1: 9037 | AT1: 9038 | AU1: 9039 | AV1: 9040 | AW1: 9037 | AX1: 9038 | AY1: 9039 | AZ1: 9040 | BA1: 9037 | BB1: 9038 | BC1: 9039 | BD1: 9040 | BE1: 9037 | BF1: 9038 | BG1: 9039 | BH1: 9040 | BI1: 9037 | BJ1: 9038 | BK1: 9039 | BL1: 9040 | BM1: 9037 | BN1: 9038 | BO1: 9039 | BP1: 9040 | BQ1: 9037 | BR1: 9038 | BS1: 9039 | BT1: 9040 | BU1: 9037 | BV1: 9038 | BW1: 9039 | BX1: 9040 | BY1: 9037 | BZ1: 9038 | CA1: 9039 | CB1: 9040 | CC1: 9037 | CD1: 9038 | CE1: 9039 | CF1: 9040 | CG1: 9037 | CH1: 9038 | CI1: 9039 | CJ1: 9040 | CK1: 9037 | CL1: 9038 | CM1: 9039 | CN1: 9040 | CO1: 9037 | CP1: 9038 | CQ1: 9039 | CR1: 9040 | CS1: 9037 | CT1: 9038 | CU1: 9039 | CV1: 9040 | CW1: 9037 | CX1: 9038 | CY1: 9039 | CZ1: 9040 | DA1: 9037 | DB1: 9038 | DC1: 9039 | DD1: 9040 | DE1: 9037 | DF1: 9038 | DG1: 9039 | DH1: 9040 | DI1: 9037 | DJ1: 9038 | DK1: 9039 | DL1: 9040 | DM1: 9037 | DN1: 9038 | DO1: 9039 | DP1: 9040 | DQ1: 9037 | DR1: 9038 | DS1: 9039 | DT1: 9040 | DU1: 9037 | DV1: 9038 | DW1: 9039 | DX1: 9040 | DY1: 9037 | DZ1: 9038 | EA1: 9039 | EB1: 9040 | EC1: 9037 | ED1: 9038 | EE1: 9039 | EF1: 9040 | EG1: 9037 | EH1: 9038 | EI1: 9039 | EJ1: 9040 | EK1: 9037 | EL1: 9038 | EM1: 9039 | EN1: 9040 | EO1: 9037 | EP1: 9038 | EQ1: 9039 | ER1: 9040 | ES1: 9037 | ET1: 9038 | EU1: 9039 | EV1: 9040 | EW1: 9037 | EX1: 9038 | EY1: 9039 | EZ1: 9040 | FA1: 9037 | FB1: 9038 | FC1: 9039 | FD1: 9040 | FE1: 9037 | FF1: 9038 | FG1: 9039 | FH1: 9040 | FI1: 9037 | FJ1: 9038 | FK1: 9039 | FL1: 9040 | FM1: 9037 | FN1: 9038 | FO1: 9039 | FP1: 9040 | FQ1: 9037 | FR1: 9038 | FS1: 9039 | FT1: 9040 | FU1: 9037 | FV1: 9038 | FW1: 9039 | FX1: 9040 | FY1: 9037 | FZ1: 9038 | GA1: 9039 | GB1: 9040 | GC1: 9037 | GD1: 9038 | GE1: 9039 | GF1: 9040 | GG1: 9037 | GH1: 9038 | GI1: 9039 | GJ1: 9040 | GK1: 9037 | GL1: 9038 | GM1: 9039 | GN1: 9040 | GO1: 9037 | GP1: 9038 | GQ1: 9039 | GR1: 9040 | GS1: 647 | GT1: 9041 | GU1: 9042 | GV1: 9043 | GW1: 9042 | GX1: 9043 | GY1: 9042 | GZ1: 9043 | HA1: 9042 | HB1: 9043 | HC1: 9042 | HD1: 9043 | HE1: 9053 | HF1: 9053 | HG1: 9053 | HH1: 9053 | HI1: 9053 | HJ1: 9053 | HK1: 9053 | HL1: 9053 | HM1: 9053 | HN1: 9053 | HO1: 9053 | HP1: 9053 | HQ1: 9053 | HR1: 9053 | HS1: 9053 | HT1: 9053 | HU1: 9053 | HV1: 9053 | HW1: 9053 | HX1: 9053 | HY1: 9053 | HZ1: 9053 | IA1: 9053 | IB1: 9053 | IC1: 9053 | ID1: 9053 | IE1: 9053 | IF1: 9053 | IG1: 9053 | IH1: 9053 | II1: 9058 | IJ1: 9058 | IK1: 9063 | IL1: 9064 | IM1: 9065 | IN1: 9066 | IO1: 9063 | IP1: 9064 | IQ1: 9065 | IR1: 9066 | IS1: 9063 | IT1: 9064 | IU1: 9065 | IV1: 9066 | IW1: 9063 | IX1: 9064 | IY1: 9065 | IZ1: 9066 | JA1: 9063 | JB1: 9064 | JC1: 9065 | JD1: 9066 | JE1: 9063 | JF1: 9064 | JG1: 9065 | JH1: 9066 | JI1: 9063 | JJ1: 9064 | JK1: 9065 | JL1: 9066 | JM1: 9063 | JN1: 9064 | JO1: 9065 | JP1: 9066 | JQ1: 9063 | JR1: 9064 | JS1: 9065 | JT1: 9066 | JU1: 9063 | JV1: 9064 | JW1: 9065 | JX1: 9066 | JY1: 6109 | JZ1: 1966 | KA1: 1217 | KB1: 2385 | KC1: 3538 | KD1: 2389 | KE1: 1560 | KF1: 137 | KG1: 95 | KH1: 807 | KI1: 1379 | KJ1: 1437 | KK1: 1567 | KL1: 1316 | KM1: 521 | KN1: 6253 | KO1: 1388 | KP1: 8653 | KQ1: 1557 | KR1: 769 | KS1: 770 | KT1: 264 | KU1: 28 | KV1: 135 | KW1: 256 | KX1: 31 | KY1: 117 | KZ1: 8205 | LA1: 8462
J2: 1 | K2: 1 | L2: 2 | M2: 2 | N2: 3 | O2: 3 | U2: 1 | V2: 2 | W2: 3 | X2: 4 | Y2: 5 | Z2: 6 | AA2: 7 | AB2: 8 | AO2: 1 | AP2: 1 | AQ2: 1 | AR2: 1 | AS2: 2 | AT2: 2 | AU2: 2 | AV2: 2 | AW2: 3 | AX2: 3 | AY2: 3 | AZ2: 3 | BA2: 4 | BB2: 4 | BC2: 4 | BD2: 4 | BE2: 5 | BF2: 5 | BG2: 5 | BH2: 5 | BI2: 6 | BJ2: 6 | BK2: 6 | BL2: 6 | BM2: 7 | BN2: 7 | BO2: 7 | BP2: 7 | BQ2: 8 | BR2: 8 | BS2: 8 | BT2: 8 | BU2: 9 | BV2: 9 | BW2: 9 | BX2: 9 | BY2: 10 | BZ2: 10 | CA2: 10 | CB2: 10 | CC2: 11 | CD2: 11 | CE2: 11 | CF2: 11 | CG2: 12 | CH2: 12 | CI2: 12 | CJ2: 12 | CK2: 13 | CL2: 13 | CM2: 13 | CN2: 13 | CO2: 14 | CP2: 14 | CQ2: 14 | CR2: 14 | CS2: 15 | CT2: 15 | CU2: 15 | CV2: 15 | CW2: 16 | CX2: 16 | CY2: 16 | CZ2: 16 | DA2: 17 | DB2: 17 | DC2: 17 | DD2: 17 | DE2: 18 | DF2: 18 | DG2: 18 | DH2: 18 | DI2: 19 | DJ2: 19 | DK2: 19 | DL2: 19 | DM2: 20 | DN2: 20 | DO2: 20 | DP2: 20 | DQ2: 21 | DR2: 21 | DS2: 21 | DT2: 21 | DU2: 22 | DV2: 22 | DW2: 22 | DX2: 22 | DY2: 23 | DZ2: 23 | EA2: 23 | EB2: 23 | EC2: 24 | ED2: 24 | EE2: 24 | EF2: 24 | EG2: 25 | EH2: 25 | EI2: 25 | EJ2: 25 | EK2: 26 | EL2: 26 | EM2: 26 | EN2: 26 | EO2: 27 | EP2: 27 | EQ2: 27 | ER2: 27 | ES2: 28 | ET2: 28 | EU2: 28 | EV2: 28 | EW2: 29 | EX2: 29 | EY2: 29 | EZ2: 29 | FA2: 30 | FB2: 30 | FC2: 30 | FD2: 30 | FE2: 31 | FF2: 31 | FG2: 31 | FH2: 31 | FI2: 32 | FJ2: 32 | FK2: 32 | FL2: 32 | FM2: 33 | FN2: 33 | FO2: 33 | FP2: 33 | FQ2: 34 | FR2: 34 | FS2: 34 | FT2: 34 | FU2: 35 | FV2: 35 | FW2: 35 | FX2: 35 | FY2: 36 | FZ2: 36 | GA2: 36 | GB2: 36 | GC2: 37 | GD2: 37 | GE2: 37 | GF2: 37 | GG2: 38 | GH2: 38 | GI2: 38 | GJ2: 38 | GK2: 39 | GL2: 39 | GM2: 39 | GN2: 39 | GO2: 40 | GP2: 40 | GQ2: 40 | GR2: 40 | GU2: 1 | GV2: 1 | GW2: 2 | GX2: 2 | GY2: 3 | GZ2: 3 | HA2: 4 | HB2: 4 | HC2: 5 | HD2: 5 | HE2: 1 | HF2: 2 | HG2: 3 | HH2: 4 | HI2: 5 | HJ2: 6 | HK2: 7 | HL2: 8 | HM2: 9 | HN2: 10 | HO2: 11 | HP2: 12 | HQ2: 13 | HR2: 14 | HS2: 15 | HT2: 16 | HU2: 17 | HV2: 18 | HW2: 19 | HX2: 20 | HY2: 21 | HZ2: 22 | IA2: 23 | IB2: 24 | IC2: 25 | ID2: 26 | IE2: 27 | IF2: 28 | IG2: 29 | IH2: 30 | II2: 1 | IJ2: 2 | IK2: 1 | IL2: 1 | IM2: 1 | IN2: 1 | IO2: 2 | IP2: 2 | IQ2: 2 | IR2: 2 | IS2: 3 | IT2: 3 | IU2: 3 | IV2: 3 | IW2: 4 | IX2: 4 | IY2: 4 | IZ2: 4 | JA2: 5 | JB2: 5 | JC2: 5 | JD2: 5 | JE2: 6 | JF2: 6 | JG2: 6 | JH2: 6 | JI2: 7 | JJ2: 7 | JK2: 7 | JL2: 7 | JM2: 8 | JN2: 8 | JO2: 8 | JP2: 8 | JQ2: 9 | JR2: 9 | JS2: 9 | JT2: 9 | JU2: 10 | JV2: 10 | JW2: 10 | JX2: 10
B3: Basic Information | F3: Branding | H3: Variant Grouping | P3: Pricing | T3: Marketing Information | AC3: Fulfillment Information | AO3: Carton Details | GS3: Compliance | HE3: Media | JY3: Attributes
B4: Required | C4: Required | D4: Recommended | E4: Required | F4: Required | G4: Conditional | H4: Recommended | I4: Conditional | J4: Conditional | K4: Conditional | L4: Conditional | M4: Conditional | N4: Conditional | O4: Conditional | P4: Required | Q4: Additional | R4: Additional | S4: Additional | T4: Conditional | U4: Conditional | V4: Conditional | W4: Conditional | X4: Conditional | Y4: Conditional | Z4: Conditional | AA4: Conditional | AB4: Conditional | AC4: Additional | AD4: Required | AE4: Required | AF4: Required | AG4: Required | AH4: Required | AI4: Conditional | AJ4: Required | AK4: Required | AL4: Conditional | AM4: Conditional | AN4: Conditional | AO4: Required | AP4: Required | AQ4: Required | AR4: Required | AS4: Conditional | AT4: Conditional | AU4: Conditional | AV4: Conditional | AW4: Conditional | AX4: Conditional | AY4: Conditional | AZ4: Conditional | BA4: Conditional | BB4: Conditional | BC4: Conditional | BD4: Conditional | BE4: Conditional | BF4: Conditional | BG4: Conditional | BH4: Conditional | BI4: Conditional | BJ4: Conditional | BK4: Conditional | BL4: Conditional | BM4: Conditional | BN4: Conditional | BO4: Conditional | BP4: Conditional | BQ4: Conditional | BR4: Conditional | BS4: Conditional | BT4: Conditional | BU4: Conditional | BV4: Conditional | BW4: Conditional | BX4: Conditional | BY4: Conditional | BZ4: Conditional | CA4: Conditional | CB4: Conditional | CC4: Conditional | CD4: Conditional | CE4: Conditional | CF4: Conditional | CG4: Conditional | CH4: Conditional | CI4: Conditional | CJ4: Conditional | CK4: Conditional | CL4: Conditional | CM4: Conditional | CN4: Conditional | CO4: Conditional | CP4: Conditional | CQ4: Conditional | CR4: Conditional | CS4: Conditional | CT4: Conditional | CU4: Conditional | CV4: Conditional | CW4: Conditional | CX4: Conditional | CY4: Conditional | CZ4: Conditional | DA4: Conditional | DB4: Conditional | DC4: Conditional | DD4: Conditional | DE4: Conditional | DF4: Conditional | DG4: Conditional | DH4: Conditional | DI4: Conditional | DJ4: Conditional | DK4: Conditional | DL4: Conditional | DM4: Conditional | DN4: Conditional | DO4: Conditional | DP4: Conditional | DQ4: Conditional | DR4: Conditional | DS4: Conditional | DT4: Conditional | DU4: Conditional | DV4: Conditional | DW4: Conditional | DX4: Conditional | DY4: Conditional | DZ4: Conditional | EA4: Conditional | EB4: Conditional | EC4: Conditional | ED4: Conditional | EE4: Conditional | EF4: Conditional | EG4: Conditional | EH4: Conditional | EI4: Conditional | EJ4: Conditional | EK4: Conditional | EL4: Conditional | EM4: Conditional | EN4: Conditional | EO4: Conditional | EP4: Conditional | EQ4: Conditional | ER4: Conditional | ES4: Conditional | ET4: Conditional | EU4: Conditional | EV4: Conditional | EW4: Conditional | EX4: Conditional | EY4: Conditional | EZ4: Conditional | FA4: Conditional | FB4: Conditional | FC4: Conditional | FD4: Conditional | FE4: Conditional | FF4: Conditional | FG4: Conditional | FH4: Conditional | FI4: Conditional | FJ4: Conditional | FK4: Conditional | FL4: Conditional | FM4: Conditional | FN4: Conditional | FO4: Conditional | FP4: Conditional | FQ4: Conditional | FR4: Conditional | FS4: Conditional | FT4: Conditional | FU4: Conditional | FV4: Conditional | FW4: Conditional | FX4: Conditional | FY4: Conditional | FZ4: Conditional | GA4: Conditional | GB4: Conditional | GC4: Conditional | GD4: Conditional | GE4: Conditional | GF4: Conditional | GG4: Conditional | GH4: Conditional | GI4: Conditional | GJ4: Conditional | GK4: Conditional | GL4: Conditional | GM4: Conditional | GN4: Conditional | GO4: Conditional | GP4: Conditional | GQ4: Conditional | GR4: Conditional | GS4: Required | GT4: Required | GU4: Conditional | GV4: Conditional | GW4: Conditional | GX4: Conditional | GY4: Conditional | GZ4: Conditional | HA4: Conditional | HB4: Conditional | HC4: Conditional | HD4: Conditional | HE4: Required | HF4: Additional | HG4: Additional | HH4: Additional | HI4: Additional | HJ4: Additional | HK4: Additional | HL4: Additional | HM4: Additional | HN4: Additional | HO4: Additional | HP4: Additional | HQ4: Additional | HR4: Additional | HS4: Additional | HT4: Additional | HU4: Additional | HV4: Additional | HW4: Additional | HX4: Additional | HY4: Additional | HZ4: Additional | IA4: Additional | IB4: Additional | IC4: Additional | ID4: Additional | IE4: Additional | IF4: Additional | IG4: Additional | IH4: Additional | II4: Additional | IJ4: Additional | IK4: Conditional | IL4: Additional | IM4: Additional | IN4: Additional | IO4: Conditional | IP4: Additional | IQ4: Additional | IR4: Additional | IS4: Conditional | IT4: Additional | IU4: Additional | IV4: Additional | IW4: Conditional | IX4: Additional | IY4: Additional | IZ4: Additional | JA4: Conditional | JB4: Additional | JC4: Additional | JD4: Additional | JE4: Conditional | JF4: Additional | JG4: Additional | JH4: Additional | JI4: Conditional | JJ4: Additional | JK4: Additional | JL4: Additional | JM4: Conditional | JN4: Additional | JO4: Additional | JP4: Additional | JQ4: Conditional | JR4: Additional | JS4: Additional | JT4: Additional | JU4: Conditional | JV4: Additional | JW4: Additional | JX4: Additional | JY4: Required | JZ4: Recommended | KA4: Required | KB4: Required | KC4: Required | KD4: Recommended | KE4: Recommended | KF4: Recommended | KG4: Additional | KH4: Required | KI4: Recommended | KJ4: Recommended | KK4: Recommended | KL4: Required | KM4: Recommended | KN4: Required | KO4: Conditional | KP4: Recommended | KQ4: Recommended | KR4: Required | KS4: Required | KT4: Required | KU4: Recommended | KV4: Conditional | KW4: Recommended | KX4: Required | KY4: Required | KZ4: Recommended | LA4: Recommended
A5: Errors | B5: Supplier Part Number | C5: Manufacturer Part Number | D5: Universal Product Code | E5: Product Name | F5: Brand | G5: Collection Name | H5: Variant Type | I5: Group Reference ID | J5: Variant Grouping 1 | K5: Variant Attribute Name On Site 1 | L5: Variant Grouping 2 | M5: Variant Attribute Name On Site 2 | N5: Variant Grouping 3 | O5: Variant Attribute Name On Site 3 | P5: Base Cost | Q5: Everyday B2B Discount Rate | R5: Minimum Advertised Price | S5: Manufacturer Suggested Retail Price | T5: Marketing Copy | U5: Feature Bullet 1 | V5: Feature Bullet 2 | W5: Feature Bullet 3 | X5: Feature Bullet 4 | Y5: Feature Bullet 5 | Z5: Feature Bullet 6 | AA5: Feature Bullet 7 | AB5: Feature Bullet 8 | AC5: Amazon Seller SKU | AD5: Minimum Order Quantity | AE5: Force Quantity Multiplier | AF5: Display Set Quantity | AG5: Product Weight | AH5: Ship Type | AI5: Freight Class | AJ5: Lead Time | AK5: Replacement Lead Time | AL5: National Motor Freight Class | AM5: Flat Pack | AN5: Ship Palletized | AO5: Carton Weight 1 | AP5: Carton Height 1 | AQ5: Carton Width 1 | AR5: Carton Depth 1 | AS5: Carton Weight 2 | AT5: Carton Height 2 | AU5: Carton Width 2 | AV5: Carton Depth 2 | AW5: Carton Weight 3 | AX5: Carton Height 3 | AY5: Carton Width 3 | AZ5: Carton Depth 3 | BA5: Carton Weight 4 | BB5: Carton Height 4 | BC5: Carton Width 4 | BD5: Carton Depth 4 | BE5: Carton Weight 5 | BF5: Carton Height 5 | BG5: Carton Width 5 | BH5: Carton Depth 5 | BI5: Carton Weight 6 | BJ5: Carton Height 6 | BK5: Carton Width 6 | BL5: Carton Depth 6 | BM5: Carton Weight 7 | BN5: Carton Height 7 | BO5: Carton Width 7 | BP5: Carton Depth 7 | BQ5: Carton Weight 8 | BR5: Carton Height 8 | BS5: Carton Width 8 | BT5: Carton Depth 8 | BU5: Carton Weight 9 | BV5: Carton Height 9 | BW5: Carton Width 9 | BX5: Carton Depth 9 | BY5: Carton Weight 10 | BZ5: Carton Height 10 | CA5: Carton Width 10 | CB5: Carton Depth 10 | CC5: Carton Weight 11 | CD5: Carton Height 11 | CE5: Carton Width 11 | CF5: Carton Depth 11 | CG5: Carton Weight 12 | CH5: Carton Height 12 | CI5: Carton Width 12 | CJ5: Carton Depth 12 | CK5: Carton Weight 13 | CL5: Carton Height 13 | CM5: Carton Width 13 | CN5: Carton Depth 13 | CO5: Carton Weight 14 | CP5: Carton Height 14 | CQ5: Carton Width 14 | CR5: Carton Depth 14 | CS5: Carton Weight 15 | CT5: Carton Height 15 | CU5: Carton Width 15 | CV5: Carton Depth 15 | CW5: Carton Weight 16 | CX5: Carton Height 16 | CY5: Carton Width 16 | CZ5: Carton Depth 16 | DA5: Carton Weight 17 | DB5: Carton Height 17 | DC5: Carton Width 17 | DD5: Carton Depth 17 | DE5: Carton Weight 18 | DF5: Carton Height 18 | DG5: Carton Width 18 | DH5: Carton Depth 18 | DI5: Carton Weight 19 | DJ5: Carton Height 19 | DK5: Carton Width 19 | DL5: Carton Depth 19 | DM5: Carton Weight 20 | DN5: Carton Height 20 | DO5: Carton Width 20 | DP5: Carton Depth 20 | DQ5: Carton Weight 21 | DR5: Carton Height 21 | DS5: Carton Width 21 | DT5: Carton Depth 21 | DU5: Carton Weight 22 | DV5: Carton Height 22 | DW5: Carton Width 22 | DX5: Carton Depth 22 | DY5: Carton Weight 23 | DZ5: Carton Height 23 | EA5: Carton Width 23 | EB5: Carton Depth 23 | EC5: Carton Weight 24 | ED5: Carton Height 24 | EE5: Carton Width 24 | EF5: Carton Depth 24 | EG5: Carton Weight 25 | EH5: Carton Height 25 | EI5: Carton Width 25 | EJ5: Carton Depth 25 | EK5: Carton Weight 26 | EL5: Carton Height 26 | EM5: Carton Width 26 | EN5: Carton Depth 26 | EO5: Carton Weight 27 | EP5: Carton Height 27 | EQ5: Carton Width 27 | ER5: Carton Depth 27 | ES5: Carton Weight 28 | ET5: Carton Height 28 | EU5: Carton Width 28 | EV5: Carton Depth 28 | EW5: Carton Weight 29 | EX5: Carton Height 29 | EY5: Carton Width 29 | EZ5: Carton Depth 29 | FA5: Carton Weight 30 | FB5: Carton Height 30 | FC5: Carton Width 30 | FD5: Carton Depth 30 | FE5: Carton Weight 31 | FF5: Carton Height 31 | FG5: Carton Width 31 | FH5: Carton Depth 31 | FI5: Carton Weight 32 | FJ5: Carton Height 32 | FK5: Carton Width 32 | FL5: Carton Depth 32 | FM5: Carton Weight 33 | FN5: Carton Height 33 | FO5: Carton Width 33 | FP5: Carton Depth 33 | FQ5: Carton Weight 34 | FR5: Carton Height 34 | FS5: Carton Width 34 | FT5: Carton Depth 34 | FU5: Carton Weight 35 | FV5: Carton Height 35 | FW5: Carton Width 35 | FX5: Carton Depth 35 | FY5: Carton Weight 36 | FZ5: Carton Height 36 | GA5: Carton Width 36 | GB5: Carton Depth 36 | GC5: Carton Weight 37 | GD5: Carton Height 37 | GE5: Carton Width 37 | GF5: Carton Depth 37 | GG5: Carton Weight 38 | GH5: Carton Height 38 | GI5: Carton Width 38 | GJ5: Carton Depth 38 | GK5: Carton Weight 39 | GL5: Carton Height 39 | GM5: Carton Width 39 | GN5: Carton Depth 39 | GO5: Carton Weight 40 | GP5: Carton Height 40 | GQ5: Carton Width 40 | GR5: Carton Depth 40 | GS5: Country of Origin | GT5: Warning Required | GU5: Chemical 1 | GV5: Toxicity 1 | GW5: Chemical 2 | GX5: Toxicity 2 | GY5: Chemical 3 | GZ5: Toxicity 3 | HA5: Chemical 4 | HB5: Toxicity 4 | HC5: Chemical 5 | HD5: Toxicity 5 | HE5: Image File Name or URL 1 | HF5: Image File Name or URL 2 | HG5: Image File Name or URL 3 | HH5: Image File Name or URL 4 | HI5: Image File Name or URL 5 | HJ5: Image File Name or URL 6 | HK5: Image File Name or URL 7 | HL5: Image File Name or URL 8 | HM5: Image File Name or URL 9 | HN5: Image File Name or URL 10 | HO5: Image File Name or URL 11 | HP5: Image File Name or URL 12 | HQ5: Image File Name or URL 13 | HR5: Image File Name or URL 14 | HS5: Image File Name or URL 15 | HT5: Image File Name or URL 16 | HU5: Image File Name or URL 17 | HV5: Image File Name or URL 18 | HW5: Image File Name or URL 19 | HX5: Image File Name or URL 20 | HY5: Image File Name or URL 21 | HZ5: Image File Name or URL 22 | IA5: Image File Name or URL 23 | IB5: Image File Name or URL 24 | IC5: Image File Name or URL 25 | ID5: Image File Name or URL 26 | IE5: Image File Name or URL 27 | IF5: Image File Name or URL 28 | IG5: Image File Name or URL 29 | IH5: Image File Name or URL 30 | II5: Video File Name or URL 1 | IJ5: Video File Name or URL 2 | IK5: Document File Name or URL 1 | IL5: Document Type 1 | IM5: Legal Document Type 1 | IN5: Document Region 1 | IO5: Document File Name or URL 2 | IP5: Document Type 2 | IQ5: Legal Document Type 2 | IR5: Document Region 2 | IS5: Document File Name or URL 3 | IT5: Document Type 3 | IU5: Legal Document Type 3 | IV5: Document Region 3 | IW5: Document File Name or URL 4 | IX5: Document Type 4 | IY5: Legal Document Type 4 | IZ5: Document Region 4 | JA5: Document File Name or URL 5 | JB5: Document Type 5 | JC5: Legal Document Type 5 | JD5: Document Region 5 | JE5: Document File Name or URL 6 | JF5: Document Type 6 | JG5: Legal Document Type 6 | JH5: Document Region 6 | JI5: Document File Name or URL 7 | JJ5: Document Type 7 | JK5: Legal Document Type 7 | JL5: Document Region 7 | JM5: Document File Name or URL 8 | JN5: Document Type 8 | JO5: Legal Document Type 8 | JP5: Document Region 8 | JQ5: Document File Name or URL 9 | JR5: Document Type 9 | JS5: Legal Document Type 9 | JT5: Document Region 9 | JU5: Document File Name or URL 10 | JV5: Document Type 10 | JW5: Legal Document Type 10 | JX5: Document Region 10 | JY5: Product Type | JZ5: Subject | KA5: Surface Type | KB5: Material | KC5: Compatible Surfaces | KD5: Personalization or Monogramming | KE5: Room Use | KF5: Holiday / Occasion | KG5: Country of Origin - Additional Details | KH5: BPA Free | KI5: Licensed Product Category | KJ5: Durability | KK5: Adjustability Features | KL5: Color | KM5: Total Number of Pieces Included | KN5: Pieces Included | KO5: Movie / Show Series Name | KP5: General Features | KQ5: Age Group | KR5: Overall Height - Top to Bottom | KS5: Overall Width - Side to Side | KT5: Overall Product Weight | KU5: Commercial Warranty | KV5: Commercial Warranty Length | KW5: Wayfair Compliance Vetting Program (including Baby Safety Alliance fka JPMA) for this product category | KX5: Uniform Packaging and Labeling Regulations (UPLR) Compliant | KY5: Canada Product Restriction | KZ5: ISTA Certified | LA5: Sustainability & Social Responsibility Certifications (North America Only)
